Workbook

Sheet 00_DASHBOARD
B2: 🏢 SFM TECHNOLOGIES — PILOTAGE DE LA PERFORMANCE SMQ 2026
B3: COCKPIT DE PILOTAGE · SMQ ISO 9001:2015 · Tableau de bord dynamique | G3: 📅 Mois : | H3: ='03_SUIVI_DATA'!E2 -> Juin
B5: 📊 PERFORMANCE GLOBALE | D5: 🚨 ALERTES CRITIQUES | F5: 🏅 ISO 9001 OQ-37 | H5: ⏰ RETARDS PLAN
B6: =IFERROR(IF(AVERAGE('6.2.1 Objectifs SMART'!L6:L54)=0,"S.O.",AVERAGE('6.2.1 Objectifs SMART'!L6:L54)),"S.O.") -> 0.025641026 | D6: =COUNTIF('6.2.1 Objectifs SMART'!M:M,"Alerte") -> 38 | F6: =IFERROR(IF('6.2.1 Objectifs SMART'!K50="","En attente",IF('6.2.1 Objectifs SMART'!K50>=1,"✅ OBTENUE",TEXT('6.2.1 Objectifs SMART'!K50,"0%")&" atteint")),"En att.") -> 0% atteint | H6: =COUNTIF('6.2.2 Plan d''Actions'!H:H,"⚠️ RETARD") -> 7
B7: Moy. % Atteinte — 40 KPI | D7: KPI < 50% — zone rouge | F7: Priorité PFE — Certification | H7: Actions plan dépassées
B9: 📡 RADAR DE PERFORMANCE PAR PROCESSUS — SMQ SFM TECHNOLOGIES 2026 | K9: ⚠️ ACTIONS CORRECTIVES PRIORITAIRES — EN RETARD
K10: Réf. | L10: Action (résumé) | M10: Statut
K11: ='6.2.2 Plan d''Actions'!A7 -> OQ-02 | L11: =LEFT('6.2.2 Plan d''Actions'!D7,80)&"..." -> Figer les roadmaps BU en janvier. Mettre en place un processus de validation de ... | M11: ='6.2.2 Plan d''Actions'!F7 -> En cours
K12: ='6.2.2 Plan d''Actions'!A28 -> OQ-20 | L12: =LEFT('6.2.2 Plan d''Actions'!D28,80)&"..." -> Définir l'objectif CA Formation avec la direction. Intégrer l'IA dans les progra... | M12: ='6.2.2 Plan d''Actions'!F28 -> À planifier
K13: ='6.2.2 Plan d''Actions'!A37 -> OQ-27 | L13: =LEFT('6.2.2 Plan d''Actions'!D37,80)&"..." -> Automatiser la production des KPIs financiers via COSAP. Diffuser par mail à la ... | M13: ='6.2.2 Plan d''Actions'!F37 -> En cours
K14: ='6.2.2 Plan d''Actions'!A38 -> OQ-28 | L14: =LEFT('6.2.2 Plan d''Actions'!D38,80)&"..." -> Finaliser le développement du module financier COSAP. Tester les fonctionnalités... | M14: ='6.2.2 Plan d''Actions'!F38 -> En cours
K15: ='6.2.2 Plan d''Actions'!A26 -> OQ-19 | L15: =LEFT('6.2.2 Plan d''Actions'!D26,80)&"..." -> Optimiser les charges BU Digital. Augmenter le CA par diversification produits. ... | M15: ='6.2.2 Plan d''Actions'!F26 -> En cours
K20: 📋 SYNTHÈSE — % Atteinte Moyen par Processus
K21: Processus | L21: Libellé | M21: Score
K22: =_MOTEUR_!$A$2 -> PM1 | L22: =_MOTEUR_!$B$2 -> Planif. Stratégique | M22: =IFERROR(IF(_MOTEUR_!C2>=0.9,"✅ Atteint",IF(_MOTEUR_!C2>=0.5,"🟡 En cours","🔴 Alerte")),"—") -> 🔴 Alerte
K23: =_MOTEUR_!$A$3 -> PR1 | L23: =_MOTEUR_!$B$3 -> BU Telco | M23: =IFERROR(IF(_MOTEUR_!C3>=0.9,"✅ Atteint",IF(_MOTEUR_!C3>=0.5,"🟡 En cours","🔴 Alerte")),"—") -> 🔴 Alerte
K24: =_MOTEUR_!$A$4 -> PR2 | L24: =_MOTEUR_!$B$4 -> BU Digital | M24: =IFERROR(IF(_MOTEUR_!C4>=0.9,"✅ Atteint",IF(_MOTEUR_!C4>=0.5,"🟡 En cours","🔴 Alerte")),"—") -> 🔴 Alerte
K25: =_MOTEUR_!$A$5 -> PR3 | L25: =_MOTEUR_!$B$5 -> BU Formation | M25: =IFERROR(IF(_MOTEUR_!C5>=0.9,"✅ Atteint",IF(_MOTEUR_!C5>=0.5,"🟡 En cours","🔴 Alerte")),"—") -> 🔴 Alerte
K26: =_MOTEUR_!$A$6 -> PS1 | L26: =_MOTEUR_!$B$6 -> RH & Compétences | M26: =IFERROR(IF(_MOTEUR_!C6>=0.9,"✅ Atteint",IF(_MOTEUR_!C6>=0.5,"🟡 En cours","🔴 Alerte")),"—") -> 🔴 Alerte
K27: =_MOTEUR_!$A$7 -> PS2 | L27: =_MOTEUR_!$B$7 -> Finance & Admin | M27: =IFERROR(IF(_MOTEUR_!C7>=0.9,"✅ Atteint",IF(_MOTEUR_!C7>=0.5,"🟡 En cours","🔴 Alerte")),"—") -> 🔴 Alerte
K28: =_MOTEUR_!$A$8 -> PS3 | L28: =_MOTEUR_!$B$8 -> Infrastructure IT | M28: =IFERROR(IF(_MOTEUR_!C8>=0.9,"✅ Atteint",IF(_MOTEUR_!C8>=0.5,"🟡 En cours","🔴 Alerte")),"—") -> 🔴 Alerte
K29: =_MOTEUR_!$A$9 -> PS4 | L29: =_MOTEUR_!$B$9 -> Commercial B.O. | M29: =IFERROR(IF(_MOTEUR_!C9>=0.9,"✅ Atteint",IF(_MOTEUR_!C9>=0.5,"🟡 En cours","🔴 Alerte")),"—") -> 🔴 Alerte
B30: SFM TECHNOLOGIES · ISO 9001:2015 · Dashboard dynamique · Données : 01_OBJECTIFS + 02_PLAN_ACTIONS · © PFE 2026

Sheet 6.2.1 Objectifs SMART
A1: OBJECTIFS QUALITÉ — CLAUSE 6.2.1 | SFM TECHNOLOGIES | ISO 9001:2015
A2: 6.2.1 — Les objectifs qualité sont cohérents avec la politique qualité, mesurables, surveillés, communiqués et mis à jour
A4: Réf. | B4: Processus | C4: Clause ISO 9001 | D4: Axe Politique Qualité (PQ-SFM) | E4: Objectif SMART 2026 | F4: Indicateur KPI | G4: Fréquence Suivi | H4: Sens KPI | I4: Valeur Actuelle (2025) | J4: Cible 2026 | K4: Réalisé (actuel) | L4: % Atteinte | M4: Statut | N4: Pilote Processus | O4: Responsable Suivi Qualité
A5: PM1 — MANAGEMENT : Planification Stratégique & Objectifs Qualité
A6: OQ-01 | B6: PM1 | C6: 6.2 · 9.3 | D6: Pilotage par la performance | E6: Atteindre un CA supérieur de 30% à 2024 avec un résultat net minimum de 30% sur l'exercice 2026 | F6: CA 2026 / CA 2024 × 100 ; Résultat net / CA × 100 | G6: Trimestriel | H6: MAX | I6: 0 | J6: 0.3 | K6: =IFERROR(INDEX('03_SUIVI_DATA'!$E$5:$P$200,MATCH($A6,'03_SUIVI_DATA'!$B$5:$B$200,0),MATCH('03_SUIVI_DATA'!$E$2,'03_SUIVI_DATA'!$E$4:$P$4,0)),"") -> 0 | L6: =IF(OR(K6="",J6=0),"",IF(H6="MAX",K6/J6,IF(K6<=J6,1,J6/K6))) -> 0 | M6: Alerte | N6: Directeur Général | O6: RAF / PS2
A7: OQ-02 | B7: PM1 | C7: 6.1 · 6.2 | D7: Pilotage par la performance | E7: Figer les roadmaps annuelles avec 1 modification maximum par an pour stabiliser la qualité et la rentabilité | F7: Nb modifications roadmap / an | G7: Semestriel | H7: MIN | I7: ≥ 3 modif. | J7: 1 | K7: =IFERROR(INDEX('03_SUIVI_DATA'!$E$5:$P$200,MATCH($A7,'03_SUIVI_DATA'!$B$5:$B$200,0),MATCH('03_SUIVI_DATA'!$E$2,'03_SUIVI_DATA'!$E$4:$P$4,0)),"") -> 0 | L7: =IF(OR(K7="",J7=0),"",IF(H7="MAX",K7/J7,IF(K7<=J7,1,J7/K7))) -> 1 | M7: =IF(K7="","À saisir",IF(L7="","",IF(L7<0.5,"Alerte",IF(L7<0.9,"En cours","Terminé")))) -> Terminé | N7: Directeur Général | O7: PMO-Qualité
A8: OQ-03 | B8: PM1 | C8: 7.1.6 | D8: Innovation et excellence technologique | E8: Intégrer l'IA dans tous les processus SFM pour un gain de productivité de 20 à 30% mesuré en 2026 | F8: % gain productivité IA mesuré vs baseline 2025 | G8: Semestriel | H8: MAX | I8: Baseline | J8: 0.2 | K8: =IFERROR(INDEX('03_SUIVI_DATA'!$E$5:$P$200,MATCH($A8,'03_SUIVI_DATA'!$B$5:$B$200,0),MATCH('03_SUIVI_DATA'!$E$2,'03_SUIVI_DATA'!$E$4:$P$4,0)),"") -> 0 | L8: =IF(OR(K8="",J8=0),"",IF(H8="MAX",K8/J8,IF(K8<=J8,1,J8/K8))) -> 0 | M8: =IF(K8="","À saisir",IF(L8="","",IF(L8<0.5,"Alerte",IF(L8<0.9,"En cours","Terminé")))) -> Alerte | N8: Dir. Exécutif Digital | O8: PMO-Qualité
A9: OQ-04 | B9: PM1 | C9: 8.4 | D9: Performance commerciale | E9: Expansion vers 6 pays africains stratégiques — développer le réseau de partenaires locaux | F9: Nb pays avec partenaire local actif / 6 | G9: Semestriel | H9: MAX | I9: 0 | J9: 6 | K9: =IFERROR(INDEX('03_SUIVI_DATA'!$E$5:$P$200,MATCH($A9,'03_SUIVI_DATA'!$B$5:$B$200,0),MATCH('03_SUIVI_DATA'!$E$2,'03_SUIVI_DATA'!$E$4:$P$4,0)),"") -> 0 | L9: =IF(OR(K9="",J9=0),"",IF(H9="MAX",K9/J9,IF(K9<=J9,1,J9/K9))) -> 0 | M9: =IF(K9="","À saisir",IF(L9="","",IF(L9<0.5,"Alerte",IF(L9<0.9,"En cours","Terminé")))) -> Alerte | N9: Directeur Général | O9: Dir. Commercial
A10: OQ-05 | B10: PM1 | C10: 8.2 | D10: Pilotage par la performance | E10: Tenir 50% du temps des équipes techniques contractualisé — maximiser la rentabilité des BU | F10: % temps équipes tech. contractualisé / temps disponible | G10: Mensuel | H10: MAX | I10: ~35% | J10: 0.5 | K10: =IFERROR(INDEX('03_SUIVI_DATA'!$E$5:$P$200,MATCH($A10,'03_SUIVI_DATA'!$B$5:$B$200,0),MATCH('03_SUIVI_DATA'!$E$2,'03_SUIVI_DATA'!$E$4:$P$4,0)),"") -> 0 | L10: =IF(OR(K10="",J10=0),"",IF(H10="MAX",K10/J10,IF(K10<=J10,1,J10/K10))) -> 0 | M10: =IF(K10="","À saisir",IF(L10="","",IF(L10<0.5,"Alerte",IF(L10<0.9,"En cours","Terminé")))) -> Alerte | N10: Directeur Général | O10: Tous Chefs BU
A11: PR1 — RÉALISATION : BU Conseil, Ingénierie & Solutions Telco
A12: OQ-06 | B12: PR1 | C12: 8.2 | D12: Performance commerciale | E12: Démarrer l'activité cybersécurité avec 2 opportunités concrètes signées dans l'année (contrats conseil) | F12: Nb contrats cybersécurité signés / an | G12: Trimestriel | H12: MAX | I12: 0 | J12: 2 | K12: =IFERROR(INDEX('03_SUIVI_DATA'!$E$5:$P$200,MATCH($A12,'03_SUIVI_DATA'!$B$5:$B$200,0),MATCH('03_SUIVI_DATA'!$E$2,'03_SUIVI_DATA'!$E$4:$P$4,0)),"") -> 0 | L12: =IF(OR(K12="",J12=0),"",IF(H12="MAX",K12/J12,IF(K12<=J12,1,J12/K12))) -> 0 | M12: =IF(K12="","À saisir",IF(L12="","",IF(L12<0.5,"Alerte",IF(L12<0.9,"En cours","Terminé")))) -> Alerte | N12: Dir. Exécutif Telco | O12: Resp. Commercial
A13: OQ-07 | B13: PR1 | C13: 8.5 | D13: Innovation et excellence technologique | E13: Migrer le module OrQoEstra QoS vers le cloud — complétion avant mi-2026, tester chez 5 régulateurs africains | F13: Migration réalisée (Oui/Non) ; Nb régulateurs testeurs | G13: Mensuel | H13: MAX | I13: Non / 0 | J13: 5 | K13: =IFERROR(INDEX('03_SUIVI_DATA'!$E$5:$P$200,MATCH($A13,'03_SUIVI_DATA'!$B$5:$B$200,0),MATCH('03_SUIVI_DATA'!$E$2,'03_SUIVI_DATA'!$E$4:$P$4,0)),"") -> 0 | L13: =IF(OR(K13="",J13=0),"",IF(H13="MAX",K13/J13,IF(K13<=J13,1,J13/K13))) -> 0 | M13: =IF(K13="","À saisir",IF(L13="","",IF(L13<0.5,"Alerte",IF(L13<0.9,"En cours","Terminé")))) -> Alerte | N13: Dir. Exécutif Telco | O13: Resp. IT / PS3
A14: OQ-08 | B14: PR1 | C14: 8.1 | D14: Innovation et excellence technologique | E14: Reprendre et finaliser QoEntum F avec prototype fonctionnel opérationnel livré en 2026 | F14: Prototype fonctionnel livré (Oui/Non) | G14: Mensuel | H14: MAX | I14: Non | J14: 1 | K14: =IFERROR(INDEX('03_SUIVI_DATA'!$E$5:$P$200,MATCH($A14,'03_SUIVI_DATA'!$B$5:$B$200,0),MATCH('03_SUIVI_DATA'!$E$2,'03_SUIVI_DATA'!$E$4:$P$4,0)),"") -> 0 | L14: =IF(OR(K14="",J14=0),"",IF(H14="MAX",K14/J14,IF(K14<=J14,1,J14/K14))) -> 0 | M14: =IF(K14="","À saisir",IF(L14="","",IF(L14<0.5,"Alerte",IF(L14<0.9,"En cours","Terminé")))) -> Alerte | N14: Dir. Exécutif Telco | O14: Chef BU R&D
A15: OQ-09 | B15: PR1 | C15: 8.2 | D15: Satisfaction et fidélisation clients | E15: Faire de SFM une référence conseil TIC — 5 études publiées et 10 projets TIC signés dans l'année | F15: Nb études publiées + Nb projets TIC signés | G15: Trimestriel | H15: MAX | I15: 0 / 0 | J15: 15 | K15: =IFERROR(INDEX('03_SUIVI_DATA'!$E$5:$P$200,MATCH($A15,'03_SUIVI_DATA'!$B$5:$B$200,0),MATCH('03_SUIVI_DATA'!$E$2,'03_SUIVI_DATA'!$E$4:$P$4,0)),"") -> 0 | L15: =IF(OR(K15="",J15=0),"",IF(H15="MAX",K15/J15,IF(K15<=J15,1,J15/K15))) -> 0 | M15: =IF(K15="","À saisir",IF(L15="","",IF(L15<0.5,"Alerte",IF(L15<0.9,"En cours","Terminé")))) -> Alerte | N15: Dir. Exécutif Telco | O15: Resp. Commercial
A16: OQ-10 | B16: PR1 | C16: 8.5 | D16: Satisfaction et fidélisation clients | E16: Boucler les projets en cours avec attestations de bonne fin : 50% dans les délais, 30% dans les 2 mois suivants | F16: % projets Telco avec attestation bonne fin dans délai | G16: Mensuel | H16: MAX | I16: ~35% | J16: 0.8 | K16: =IFERROR(INDEX('03_SUIVI_DATA'!$E$5:$P$200,MATCH($A16,'03_SUIVI_DATA'!$B$5:$B$200,0),MATCH('03_SUIVI_DATA'!$E$2,'03_SUIVI_DATA'!$E$4:$P$4,0)),"") -> 0 | L16: =IF(OR(K16="",J16=0),"",IF(H16="MAX",K16/J16,IF(K16<=J16,1,J16/K16))) -> 0 | M16: =IF(K16="","À saisir",IF(L16="","",IF(L16<0.5,"Alerte",IF(L16<0.9,"En cours","Terminé")))) -> Alerte | N16: Dir. Exécutif Telco | O16: Chef BU / PMO
A17: OQ-11 | B17: PR1 | C17: 8.2 | D17: Performance commerciale | E17: Acquérir 3 nouveaux clients anglophones (Nigeria, Kenya, Ghana) — au-delà des prospects déjà en cours depuis 2024 | F17: Nb nouveaux clients anglophones signés (hors prospects 2024) | G17: Trimestriel | H17: MAX | I17: 0 | J17: 3 | K17: =IFERROR(INDEX('03_SUIVI_DATA'!$E$5:$P$200,MATCH($A17,'03_SUIVI_DATA'!$B$5:$B$200,0),MATCH('03_SUIVI_DATA'!$E$2,'03_SUIVI_DATA'!$E$4:$P$4,0)),"") -> 0 | L17: =IF(OR(K17="",J17=0),"",IF(H17="MAX",K17/J17,IF(K17<=J17,1,J17/K17))) -> 0 | M17: =IF(K17="","À saisir",IF(L17="","",IF(L17<0.5,"Alerte",IF(L17<0.9,"En cours","Terminé")))) -> Alerte | N17: Dir. Exécutif Telco | O17: Dir. Commercial
A18: OQ-12 | B18: PR1 | C18: 8.2 · 9.3 | D18: Pilotage par la performance | E18: Augmentation du CA BU Telco de 20% avec marge nette de 30% par rapport à 2024 | F18: CA BU Telco 2026 / CA 2024 × 100 ; Marge nette BU Telco | G18: Trimestriel | H18: MAX | I18: 0 | J18: 0.2 | K18: =IFERROR(INDEX('03_SUIVI_DATA'!$E$5:$P$200,MATCH($A18,'03_SUIVI_DATA'!$B$5:$B$200,0),MATCH('03_SUIVI_DATA'!$E$2,'03_SUIVI_DATA'!$E$4:$P$4,0)),"") -> 0 | L18: =IF(OR(K18="",J18=0),"",IF(H18="MAX",K18/J18,IF(K18<=J18,1,J18/K18))) -> 0 | M18: =IF(K18="","À saisir",IF(L18="","",IF(L18<0.5,"Alerte",IF(L18<0.9,"En cours","Terminé")))) -> Alerte | N18: Dir. Exécutif Telco | O18: RAF / PS2
A19: PR2 — RÉALISATION : BU Conseil, Transformation Digitale & Solutions Entreprises
A20: OQ-13 | B20: PR2 | C20: 8.1 | D20: Innovation et excellence technologique | E20: Lancer COSAP commercialement — min 2 ventes confirmées, plateforme en production avec UX améliorée, taux remplissage ≥ 90% | F20: Nb ventes COSAP + Taux remplissage équipes (%) | G20: Mensuel | H20: MAX | I20: 0 / <50% | J20: 2 | K20: =IFERROR(INDEX('03_SUIVI_DATA'!$E$5:$P$200,MATCH($A20,'03_SUIVI_DATA'!$B$5:$B$200,0),MATCH('03_SUIVI_DATA'!$E$2,'03_SUIVI_DATA'!$E$4:$P$4,0)),"") -> 0 | L20: =IF(OR(K20="",J20=0),"",IF(H20="MAX",K20/J20,IF(K20<=J20,1,J20/K20))) -> 0 | M20: =IF(K20="","À saisir",IF(L20="","",IF(L20<0.5,"Alerte",IF(L20<0.9,"En cours","Terminé")))) -> Alerte | N20: Dir. Exécutif Digital | O20: Chef BU / PS3
A21: OQ-14 | B21: PR2 | C21: 8.2 | D21: Performance commerciale | E21: Réaliser 50 k€ de CA sur SFM Connect — 3 clients France, 5 clients Tunisie, 1 par pays (Burkina / Cameroun / Côte d'Ivoire) | F21: CA SFM Connect 2026 (k€) ; Nb clients par pays | G21: Trimestriel | H21: MAX | I21: 0 | J21: 50 | K21: =IFERROR(INDEX('03_SUIVI_DATA'!$E$5:$P$200,MATCH($A21,'03_SUIVI_DATA'!$B$5:$B$200,0),MATCH('03_SUIVI_DATA'!$E$2,'03_SUIVI_DATA'!$E$4:$P$4,0)),"") -> 0 | L21: =IF(OR(K21="",J21=0),"",IF(H21="MAX",K21/J21,IF(K21<=J21,1,J21/K21))) -> 0 | M21: =IF(K21="","À saisir",IF(L21="","",IF(L21<0.5,"Alerte",IF(L21<0.9,"En cours","Terminé")))) -> Alerte | N21: Dir. Exécutif Digital | O21: Resp. Commercial
A22: OQ-15 | B22: PR2 | C22: 8.1 | D22: Innovation et excellence technologique | E22: Finaliser les produits cybersécurité SoC et SIEM — 2 PoCs ou ventes signées avant fin septembre 2026 | F22: Nb PoCs ou ventes SoC/SIEM signés avant Q3 2026 | G22: Mensuel | H22: MAX | I22: 0 | J22: 2 | K22: =IFERROR(INDEX('03_SUIVI_DATA'!$E$5:$P$200,MATCH($A22,'03_SUIVI_DATA'!$B$5:$B$200,0),MATCH('03_SUIVI_DATA'!$E$2,'03_SUIVI_DATA'!$E$4:$P$4,0)),"") -> 0 | L22: =IF(OR(K22="",J22=0),"",IF(H22="MAX",K22/J22,IF(K22<=J22,1,J22/K22))) -> 0 | M22: =IF(K22="","À saisir",IF(L22="","",IF(L22<0.5,"Alerte",IF(L22<0.9,"En cours","Terminé")))) -> Alerte | N22: Dir. Exécutif Digital | O22: Chef BU / PS3
A23: OQ-16 | B23: PR2 | C23: 7.1.6 | D23: Innovation et excellence technologique | E23: Opérationnaliser BidMaster V1 en S1 2026 — gagner 80% d'efficacité dans les processus de réponse aux AO/AMI | F23: BidMaster V1 déployé (Oui/Non) ; % gain efficacité AO mesuré | G23: Mensuel | H23: MAX | I23: Non / 0% | J23: 0.8 | K23: =IFERROR(INDEX('03_SUIVI_DATA'!$E$5:$P$200,MATCH($A23,'03_SUIVI_DATA'!$B$5:$B$200,0),MATCH('03_SUIVI_DATA'!$E$2,'03_SUIVI_DATA'!$E$4:$P$4,0)),"") -> 0 | L23: =IF(OR(K23="",J23=0),"",IF(H23="MAX",K23/J23,IF(K23<=J23,1,J23/K23))) -> 0 | M23: =IF(K23="","À saisir",IF(L23="","",IF(L23<0.5,"Alerte",IF(L23<0.9,"En cours","Terminé")))) -> Alerte | N23: Dir. Exécutif Digital | O23: PMO-Qualité
A24: OQ-17 | B24: PR2 | C24: 7.5 | D24: Innovation et excellence technologique | E24: Opérationnaliser KMS (SFM BrAIn) V1 en S1 2026 — capitalisation des connaissances internes, sécurisation des codes SFM | F24: KMS V1 opérationnel (Oui/Non) ; Nb processus documentés KMS | G24: Mensuel | H24: MAX | I24: Non / 0 | J24: 1 | K24: =IFERROR(INDEX('03_SUIVI_DATA'!$E$5:$P$200,MATCH($A24,'03_SUIVI_DATA'!$B$5:$B$200,0),MATCH('03_SUIVI_DATA'!$E$2,'03_SUIVI_DATA'!$E$4:$P$4,0)),"") -> 0 | L24: =IF(OR(K24="",J24=0),"",IF(H24="MAX",K24/J24,IF(K24<=J24,1,J24/K24))) -> 0 | M24: =IF(K24="","À saisir",IF(L24="","",IF(L24<0.5,"Alerte",IF(L24<0.9,"En cours","Terminé")))) -> Alerte | N24: Dir. Exécutif Digital | O24: Resp. IT / PS3
A25: OQ-18 | B25: PR2 | C25: 8.2 | D25: Satisfaction et fidélisation clients | E25: Lancer le nouveau site web SFM — opérationnel au plus tard le 31/05/2026 pour soutenir la prospection et la crédibilité ISO | F25: Site web lancé avant 31/05/2026 (Oui/Non) | G25: Mensuel | H25: MAX | I25: Non | J25: 1 | K25: =IFERROR(INDEX('03_SUIVI_DATA'!$E$5:$P$200,MATCH($A25,'03_SUIVI_DATA'!$B$5:$B$200,0),MATCH('03_SUIVI_DATA'!$E$2,'03_SUIVI_DATA'!$E$4:$P$4,0)),"") -> 0 | L25: =IF(OR(K25="",J25=0),"",IF(H25="MAX",K25/J25,IF(K25<=J25,1,J25/K25))) -> 0 | M25: =IF(K25="","À saisir",IF(L25="","",IF(L25<0.5,"Alerte",IF(L25<0.9,"En cours","Terminé")))) -> Alerte | N25: Dir. Exécutif Digital | O25: Resp. Commercial / PS4
A26: OQ-19 | B26: PR2 | C26: 9.3 | D26: Pilotage par la performance | E26: CA BU Digital couvrant ses charges avec une marge nette de 30% en 2026 | F26: Marge nette BU Digital / CA BU Digital × 100 | G26: Trimestriel | H26: MAX | I26: 0 | J26: 0.3 | K26: =IFERROR(INDEX('03_SUIVI_DATA'!$E$5:$P$200,MATCH($A26,'03_SUIVI_DATA'!$B$5:$B$200,0),MATCH('03_SUIVI_DATA'!$E$2,'03_SUIVI_DATA'!$E$4:$P$4,0)),"") -> 0 | L26: =IF(OR(K26="",J26=0),"",IF(H26="MAX",K26/J26,IF(K26<=J26,1,J26/K26))) -> 0 | M26: =IF(K26="","À saisir",IF(L26="","",IF(L26<0.5,"Alerte",IF(L26<0.9,"En cours","Terminé")))) -> Alerte | N26: Dir. Exécutif Digital | O26: RAF / PS2
A27: PR3 — RÉALISATION : BU Formation
A28: OQ-20 | B28: PR3 | C28: 8.2 · 9.3 | D28: Pilotage par la performance | E28: Définir et atteindre un objectif de CA Formation 2026 — intégrer l'IA dans les programmes et l'ingénierie pédagogique | F28: CA BU Formation 2026 (k€) ; IA intégrée dans les programmes (Oui/Non) | G28: Trimestriel | H28: MAX | I28: 0 | J28: 1 | K28: =IFERROR(INDEX('03_SUIVI_DATA'!$E$5:$P$200,MATCH($A28,'03_SUIVI_DATA'!$B$5:$B$200,0),MATCH('03_SUIVI_DATA'!$E$2,'03_SUIVI_DATA'!$E$4:$P$4,0)),"") -> 0 | L28: =IF(OR(K28="",J28=0),"",IF(H28="MAX",K28/J28,IF(K28<=J28,1,J28/K28))) -> 0 | M28: =IF(K28="","À saisir",IF(L28="","",IF(L28<0.5,"Alerte",IF(L28<0.9,"En cours","Terminé")))) -> Alerte | N28: Resp. Formation | O28: RAF / PS2
A29: OQ-21 | B29: PR3 | C29: 8.1 | D29: Innovation et excellence technologique | E29: Développer 5 nouveaux axes/modules de formation — 5G, IA, Cybersécurité, Data — adaptés aux régulateurs et opérateurs africains | F29: Nb nouveaux modules formation livrés et validés en 2026 | G29: Semestriel | H29: MAX | I29: 0 | J29: 5 | K29: =IFERROR(INDEX('03_SUIVI_DATA'!$E$5:$P$200,MATCH($A29,'03_SUIVI_DATA'!$B$5:$B$200,0),MATCH('03_SUIVI_DATA'!$E$2,'03_SUIVI_DATA'!$E$4:$P$4,0)),"") -> 0 | L29: =IF(OR(K29="",J29=0),"",IF(H29="MAX",K29/J29,IF(K29<=J29,1,J29/K29))) -> 0 | M29: =IF(K29="","À saisir",IF(L29="","",IF(L29<0.5,"Alerte",IF(L29<0.9,"En cours","Terminé")))) -> Alerte | N29: Resp. Formation | O29: Chef BU PR3
A30: OQ-22 | B30: PR3 | C30: 9.1.2 | D30: Satisfaction et fidélisation clients | E30: Boucler les programmes de formation en cours avec attestations, taux de satisfaction ≥ 90% et taux de réussite ≥ 80% | F30: Taux satisfaction apprenants (%) ; Taux réussite (%) | G30: Trimestriel | H30: MAX | I30: 0 | J30: 0.9 | K30: =IFERROR(INDEX('03_SUIVI_DATA'!$E$5:$P$200,MATCH($A30,'03_SUIVI_DATA'!$B$5:$B$200,0),MATCH('03_SUIVI_DATA'!$E$2,'03_SUIVI_DATA'!$E$4:$P$4,0)),"") -> 0 | L30: =IF(OR(K30="",J30=0),"",IF(H30="MAX",K30/J30,IF(K30<=J30,1,J30/K30))) -> 0 | M30: =IF(K30="","À saisir",IF(L30="","",IF(L30<0.5,"Alerte",IF(L30<0.9,"En cours","Terminé")))) -> Alerte | N30: Resp. Formation | O30: Resp. Qualité
A31: PS1 — SUPPORT : RH & Compétences
A32: OQ-23 | B32: PS1 — RH & Compétences | C32: 7.1.2 | D32: Développement des compétences collaborateurs | E32: Mener les enquêtes de satisfaction collaborateurs semestrielles — cible 80% de satisfaction minimum | F32: Taux satisfaction collaborateurs (enquête semestrielle) | G32: Semestriel | H32: MAX | I32: 0 | J32: 0.8 | K32: =IFERROR(INDEX('03_SUIVI_DATA'!$E$5:$P$200,MATCH($A32,'03_SUIVI_DATA'!$B$5:$B$200,0),MATCH('03_SUIVI_DATA'!$E$2,'03_SUIVI_DATA'!$E$4:$P$4,0)),"") -> 0 | L32: =IF(OR(K32="",J32=0),"",IF(H32="MAX",K32/J32,IF(K32<=J32,1,J32/K32))) -> 0 | M32: =IF(K32="","À saisir",IF(L32="","",IF(L32<0.5,"Alerte",IF(L32<0.9,"En cours","Terminé")))) -> Alerte | N32: DRH | O32: Resp. RH / PS1
A33: OQ-24 | B33: PS1 — RH & Compétences | C33: 7.2 | D33: Développement des compétences collaborateurs | E33: Assurer la montée en compétences de toutes les équipes — chaque collaborateur participe à ≥ 1 projet hors de sa spécialité | F33: % collaborateurs techniques ayant participé à 1 projet hors spécialité | G33: Annuel | H33: MAX | I33: 0 | J33: 1 | K33: =IFERROR(INDEX('03_SUIVI_DATA'!$E$5:$P$200,MATCH($A33,'03_SUIVI_DATA'!$B$5:$B$200,0),MATCH('03_SUIVI_DATA'!$E$2,'03_SUIVI_DATA'!$E$4:$P$4,0)),"") -> 0 | L33: =IF(OR(K33="",J33=0),"",IF(H33="MAX",K33/J33,IF(K33<=J33,1,J33/K33))) -> 0 | M33: =IF(K33="","À saisir",IF(L33="","",IF(L33<0.5,"Alerte",IF(L33<0.9,"En cours","Terminé")))) -> Alerte | N33: DRH | O33: Chef BU / DRH
A34: OQ-25 | B34: PS1 — RH & Compétences | C34: 7.2 | D34: Développement des compétences collaborateurs | E34: Former un doublon pour les postes critiques (ex : doublure de Lahaou pour TariStriker) — réduire la dépendance aux personnes-clés | F34: Nb postes critiques avec doublon formé / nb postes critiques identifiés | G34: Semestriel | H34: MAX | I34: 0% | J34: 1 | K34: =IFERROR(INDEX('03_SUIVI_DATA'!$E$5:$P$200,MATCH($A34,'03_SUIVI_DATA'!$B$5:$B$200,0),MATCH('03_SUIVI_DATA'!$E$2,'03_SUIVI_DATA'!$E$4:$P$4,0)),"") -> 0 | L34: =IF(OR(K34="",J34=0),"",IF(H34="MAX",K34/J34,IF(K34<=J34,1,J34/K34))) -> 0 | M34: =IF(K34="","À saisir",IF(L34="","",IF(L34<0.5,"Alerte",IF(L34<0.9,"En cours","Terminé")))) -> Alerte | N34: DRH | O34: Resp. RH / PS1
A35: PS2 — SUPPORT : Finance & Administration
A36: OQ-26 | B36: PS2 | C36: 8.2 | D36: Pilotage par la performance | E36: Recouvrer 90% des factures dans les 2 mois suivant leur émission — réduire les délais de paiement et sécuriser la trésorerie | F36: Montant recouvré dans J+60 / montant facturé × 100 | G36: Mensuel | H36: MAX | I36: ~80% | J36: 0.9 | K36: =IFERROR(INDEX('03_SUIVI_DATA'!$E$5:$P$200,MATCH($A36,'03_SUIVI_DATA'!$B$5:$B$200,0),MATCH('03_SUIVI_DATA'!$E$2,'03_SUIVI_DATA'!$E$4:$P$4,0)),"") -> 0 | L36: =IF(OR(K36="",J36=0),"",IF(H36="MAX",K36/J36,IF(K36<=J36,1,J36/K36))) -> 0 | M36: =IF(K36="","À saisir",IF(L36="","",IF(L36<0.5,"Alerte",IF(L36<0.9,"En cours","Terminé")))) -> Alerte | N36: RAF | O36: Resp. Finance / PS2
A37: OQ-27 | B37: PS2 | C37: 9.1.3 | D37: Pilotage par la performance | E37: Envoyer les KPIs financiers mensuellement à la responsable financière et à la DG — 100% des envois réalisés | F37: Nb rapports financiers envoyés / nb mois × 100 | G37: Mensuel | H37: MAX | I37: ~70% | J37: 1 | K37: =IFERROR(INDEX('03_SUIVI_DATA'!$E$5:$P$200,MATCH($A37,'03_SUIVI_DATA'!$B$5:$B$200,0),MATCH('03_SUIVI_DATA'!$E$2,'03_SUIVI_DATA'!$E$4:$P$4,0)),"") -> 0 | L37: =IF(OR(K37="",J37=0),"",IF(H37="MAX",K37/J37,IF(K37<=J37,1,J37/K37))) -> 0 | M37: =IF(K37="","À saisir",IF(L37="","",IF(L37<0.5,"Alerte",IF(L37<0.9,"En cours","Terminé")))) -> Alerte | N37: RAF | O37: Resp. Finance / PS2
A38: OQ-28 | B38: PS2 | C38: 7.5 | D38: Amélioration continue & maîtrise processus | E38: Rendre le module financier COSAP complètement opérationnel en Q1 2026 — automatiser l'acquisition des informations financières | F38: Module COSAP Finance opérationnel (Oui/Non) | G38: Mensuel | H38: MAX | I38: Non | J38: 1 | K38: =IFERROR(INDEX('03_SUIVI_DATA'!$E$5:$P$200,MATCH($A38,'03_SUIVI_DATA'!$B$5:$B$200,0),MATCH('03_SUIVI_DATA'!$E$2,'03_SUIVI_DATA'!$E$4:$P$4,0)),"") -> 0 | L38: =IF(OR(K38="",J38=0),"",IF(H38="MAX",K38/J38,IF(K38<=J38,1,J38/K38))) -> 0 | M38: =IF(K38="","À saisir",IF(L38="","",IF(L38<0.5,"Alerte",IF(L38<0.9,"En cours","Terminé")))) -> Alerte | N38: RAF | O38: PMO-Qualité
A39: OQ-29 | B39: PS2 | C39: 9.1.3 | D39: Pilotage par la performance | E39: Maintenir une rigueur de 95% dans les états financiers — zéro erreur de calcul significative dans les bilans et reportings | F39: % états financiers sans erreur significative / an | G39: Trimestriel | H39: MAX | I39: 0 | J39: 0.95 | K39: =IFERROR(INDEX('03_SUIVI_DATA'!$E$5:$P$200,MATCH($A39,'03_SUIVI_DATA'!$B$5:$B$200,0),MATCH('03_SUIVI_DATA'!$E$2,'03_SUIVI_DATA'!$E$4:$P$4,0)),"") -> 0 | L39: =IF(OR(K39="",J39=0),"",IF(H39="MAX",K39/J39,IF(K39<=J39,1,J39/K39))) -> 0 | M39: =IF(K39="","À saisir",IF(L39="","",IF(L39<0.5,"Alerte",IF(L39<0.9,"En cours","Terminé")))) -> Alerte | N39: RAF | O39: Resp. Finance / PS2
A40: OQ-30 | B40: PS2 | C40: 8.1 | D40: Conformité aux exigences régl. & éthiques | E40: Assurer la conformité de toutes les déclarations fiscales et sociales (Tunisie + pays filiales) — zéro retard ni pénalité | F40: Nb retards ou pénalités déclarations fiscales/sociales / an | G40: Trimestriel | H40: MAX | I40: 0 | J40: 0 | K40: =IFERROR(INDEX('03_SUIVI_DATA'!$E$5:$P$200,MATCH($A40,'03_SUIVI_DATA'!$B$5:$B$200,0),MATCH('03_SUIVI_DATA'!$E$2,'03_SUIVI_DATA'!$E$4:$P$4,0)),"") -> 0 | L40: =IF(OR(K40="",J40=0),"",IF(H40="MAX",K40/J40,IF(K40<=J40,1,J40/K40))) | M40: =IF(K40="","À saisir",IF(L40="","",IF(L40<0.5,"Alerte",IF(L40<0.9,"En cours","Terminé")))) | N40: RAF | O40: Resp. Finance / PS2
A41: PS3 — SUPPORT : Infrastructure IT & Systèmes d'Information
...

Sheet 6.2.2 Plan d'Actions
A1: PLAN D'ACTIONS — CLAUSE 6.2.2 | SFM TECHNOLOGIES | ISO 9001:2015
A2: 6.2.2 — Planifier : CE QUI SERA FAIT · RESSOURCES NÉCESSAIRES · RESPONSABLE · ÉCHÉANCE · COMMENT LES RÉSULTATS SERONT ÉVALUÉS
A4: Réf. Objectif | B4: Processus | C4: Priorité | D4: Ce qui sera fait (6.2.2 a) | E4: Responsable (6.2.2 c) | F4: Statut | G4: Échéance (6.2.2 d) | H4: ⚠️ Retard | I4: Jalons Intermédiaires | J4: Ressources Nécessaires (6.2.2 b) | K4: Comment évaluer l'efficacité (6.2.2 e) | L4: Efficacité (après 3 mois)
A5: PM1 — MANAGEMENT : Planification Stratégique & Objectifs Qualité
A6: OQ-01 | B6: PM1 — Planification Stratégique | C6: Haute | D6: Développer le plan de croissance CA 2026. Consolider le tableau de bord financier mensuel. Présenter les résultats lors des revues de direction trimestrielles. | E6: Directeur Général / RAF | F6: En cours | G6: 46387 | H6: =IF(AND(G6<TODAY(),F6<>"Terminé"),"⚠️ RETARD","") | I6: Q1 : Tableau de bord CA opérationnel Q2 : 1ère revue financière Q4 : Bilan CA annuel | J6: Direction Générale · RAF · Outil COSAP ou Excel · Tableau de bord CA | K6: ≥ +30% CA vs 2024 (trimestriel) Résultat net ≥ 30% (annuel) | L6: =IF(F6="Terminé","À évaluer (J+90)","En attente") -> En attente
A7: OQ-02 | B7: PM1 — Planification Stratégique | C7: Haute | D7: Figer les roadmaps BU en janvier. Mettre en place un processus de validation de modification (≤ 1 par an). Communiquer les décisions à toutes les équipes. | E7: Directeur Général / PMO-Qualité | F7: En cours | G7: 46053 | H7: =IF(AND(G7<TODAY(),F7<>"Terminé"),"⚠️ RETARD","") -> ⚠️ RETARD | I7: Jan : Roadmaps validées Q2 : Bilan 1ère révision Q4 : Rapport modifications | J7: Direction Générale · Chefs BU · PMO · Documentation roadmaps | K7: Nb modifications roadmap ≤ 1 / an (suivi semestriel) | L7: =IF(F7="Terminé","À évaluer (J+90)","En attente") -> En attente
A8: OQ-03 | B8: PM1 — Planification Stratégique | C8: Haute | D8: Identifier les processus prioritaires pour l'IA. Déployer BidMaster et KMS SFM BrAIn. Mesurer les gains de productivité avant/après déploiement. | E8: Dir. Exécutif Digital / PMO | F8: Planifié | G8: 46387 | H8: =IF(AND(G8<TODAY(),F8<>"Terminé"),"⚠️ RETARD","") | I8: Q1 : Processus IA identifiés Q2 : Outils déployés Q4 : Mesure gains productivité | J8: Budget IA · Outils BidMaster / KMS SFM BrAIn · Équipes techniques · Formation | K8: Gain productivité ≥ 20-30% (semestriel, mesure avant/après) | L8: =IF(F8="Terminé","À évaluer (J+90)","En attente") -> En attente
A9: OQ-04 | B9: PM1 — Planification Stratégique | C9: Haute | D9: Cartographier les 6 pays africains cibles. Identifier et contractualiser avec des partenaires locaux dans chaque pays cible. | E9: Directeur Général / Dir. Commercial | F9: Planifié | G9: 46387 | H9: =IF(AND(G9<TODAY(),F9<>"Terminé"),"⚠️ RETARD","") | I9: Q1 : Cartographie pays cibles Q2 : Premiers contacts partenaires Q4 : 6 partenariats signés | J9: Direction Générale · Budget prospection internationale · Experts marché africain | K9: Nb pays avec partenaire local actif = 6 (semestriel) | L9: =IF(F9="Terminé","À évaluer (J+90)","En attente") -> En attente
A10: OQ-05 | B10: PM1 — Planification Stratégique | C10: Haute | D10: Établir planning de charge mensuel. Prioriser les affectations aux missions facturables. Tableau de bord charge vs disponibilité. | E10: Directeur Général / Tous Chefs BU | F10: En cours | G10: 46387 | H10: =IF(AND(G10<TODAY(),F10<>"Terminé"),"⚠️ RETARD","") | I10: Jan : Plan charge établi Q2 : 1er bilan contractualisation Q4 : Bilan annuel | J10: Outil COSAP · Chefs BU · PMO · Resp. Commercial | K10: % temps contractualisé ≥ 50% (mensuel) | L10: =IF(F10="Terminé","À évaluer (J+90)","En attente") -> En attente
A11: PR1 — RÉALISATION : BU Conseil, Ingénierie & Solutions Telco
A12: OQ-06 | B12: PR1 — BU Conseil & Solutions Telco | C12: Haute | D12: Prospecter 5 opportunités cybersécurité. Réaliser des démos et PoCs. Finaliser et signer 2 contrats conseil cybersécurité. | E12: Dir. Exécutif Telco / Resp. Commercial | F12: En cours | G12: 46387 | H12: =IF(AND(G12<TODAY(),F12<>"Terminé"),"⚠️ RETARD","") | I12: Q1 : Offre cybersécurité formalisée Q2 : 2 PoCs réalisés Q4 : 2 contrats signés | J12: Dir. Exécutif Telco · Resp. Commercial · Budget prospection cyber · Experts cybersécurité | K12: Nb contrats cybersécurité signés ≥ 2 (trimestriel) | L12: =IF(F12="Terminé","À évaluer (J+90)","En attente") -> En attente
A13: OQ-07 | B13: PR1 — BU Conseil & Solutions Telco | C13: Haute | D13: Finaliser migration OrQoEstra QoS vers cloud. Déployer pipeline CI/CD. Tester la solution chez 5 régulateurs africains avant mi-2026. | E13: Dir. Exécutif Telco / Resp. IT | F13: En cours | G13: 46203 | H13: =IF(AND(G13<TODAY(),F13<>"Terminé"),"⚠️ RETARD","") | I13: Mar : Migration cloud terminée Avr : Pipeline CI/CD déployé Juin : Tests chez 5 régulateurs | J13: Resp. IT · Budget cloud (estimé : 3-5 k€) · Équipe dev. OrQoEstra · Dir. Exécutif Telco | K13: Migration réalisée (Oui/Non) Nb régulateurs testeurs = 5 | L13: =IF(F13="Terminé","À évaluer (J+90)","En attente") -> En attente
A14: OQ-08 | B14: PR1 — BU Conseil & Solutions Telco | C14: Haute | D14: Reprendre la spécification de QoEntum F. Planifier le développement. Livrer un prototype fonctionnel opérationnel en 2026. | E14: Dir. Exécutif Telco / Chef BU R&D | F14: En cours | G14: 46387 | H14: =IF(AND(G14<TODAY(),F14<>"Terminé"),"⚠️ RETARD","") | I14: Q1 : Spécifications révisées Q2 : Développement 50% Q4 : Prototype fonctionnel livré | J14: Chef BU R&D · Équipe technique · Budget développement QoEntum F | K14: Prototype fonctionnel (Oui/Non) (mensuel) | L14: =IF(F14="Terminé","À évaluer (J+90)","En attente") -> En attente
A15: OQ-09 | B15: PR1 — BU Conseil & Solutions Telco | C15: Haute | D15: Planifier la publication de 5 études TIC (régulation, QoS, 5G…). Prospecter 10 projets TIC signables. Valoriser via le site web SFM. | E15: Dir. Exécutif Telco / Resp. Commercial | F15: Planifié | G15: 46387 | H15: =IF(AND(G15<TODAY(),F15<>"Terminé"),"⚠️ RETARD","") | I15: Q1 : Plan publications TIC établi Q2 : 3 études publiées Q4 : 5 études + 10 projets signés | J15: Dir. Exécutif Telco · Experts TIC · Budget communication · Resp. Commercial | K15: Nb études publiées ≥ 5 Nb projets TIC signés ≥ 10 (semestriel) | L15: =IF(F15="Terminé","À évaluer (J+90)","En attente") -> En attente
A16: OQ-10 | B16: PR1 — BU Conseil & Solutions Telco | C16: Haute | D16: Mettre en place suivi des délais par projet dans le tableau de bord PMO (COSAP). Alertes automatiques. Obtenir attestations de bonne fin. | E16: Chef BU / PMO | F16: En cours | G16: 46295 | H16: =IF(AND(G16<TODAY(),F16<>"Terminé"),"⚠️ RETARD","") | I16: Jan : Dashboard délais opérationnel Q2 : Alertes configurées Q3 : 80% attestations obtenues | J16: Tableau de bord PMO · COSAP · Chefs de BU · Resp. Qualité | K16: % projets avec attestation bonne fin ≥ 80% (mensuel) | L16: =IF(F16="Terminé","À évaluer (J+90)","En attente") -> En attente
A17: OQ-11 | B17: PR1 — BU Conseil & Solutions Telco | C17: Haute | D17: Prospecter marchés anglophones Nigeria, Kenya, Ghana. Cibler régulateurs et opérateurs. Signer 3 nouveaux clients (hors prospects 2024). | E17: Dir. Commercial / Dir. Exécutif Telco | F17: Planifié | G17: 46387 | H17: =IF(AND(G17<TODAY(),F17<>"Terminé"),"⚠️ RETARD","") | I17: Q1 : Plan prospection anglophone Q2 : 1ères présentations Q4 : 3 clients signés | J17: Dir. Commercial · Budget prospection internationale · Experts marchés anglophones | K17: Nb nouveaux clients anglophones ≥ 3 (trimestriel) | L17: =IF(F17="Terminé","À évaluer (J+90)","En attente") -> En attente
A18: OQ-12 | B18: PR1 — BU Conseil & Solutions Telco | C18: Haute | D18: Maximiser le CA BU Telco via pipeline commercial. Maîtriser les marges par projet. Reporting financier mensuel BU Telco. | E18: Dir. Exécutif Telco / RAF | F18: En cours | G18: 46387 | H18: =IF(AND(G18<TODAY(),F18<>"Terminé"),"⚠️ RETARD","") | I18: Q1 : Objectifs CA BU Telco fixés Q2 : Bilan S1 Q4 : CA +20% vs 2024 atteint | J18: Dir. Exécutif Telco · RAF · Outil CRM · COSAP | K18: CA BU Telco +20% vs 2024 Marge nette ≥ 30% (trimestriel) | L18: =IF(F18="Terminé","À évaluer (J+90)","En attente") -> En attente
A19: PR2 — RÉALISATION : BU Conseil, Transformation Digitale & Solutions Entreprises
A20: OQ-13 | B20: PR2 — BU Digital & Entreprises | C20: Haute | D20: Finaliser corrections COSAP avec UX améliorée. Lancer commercialement. Déployer chez 2 premiers clients. Atteindre 90% de taux de remplissage. | E20: Dir. Exécutif Digital / Chef BU | F20: En cours | G20: 46295 | H20: =IF(AND(G20<TODAY(),F20<>"Terminé"),"⚠️ RETARD","") | I20: Q1 : COSAP UX améliorée Q2 : 2 ventes confirmées Q3 : Taux remplissage ≥ 90% | J20: Dir. Exécutif Digital · Chef BU · Équipe dev. COSAP · Budget marketing SaaS | K20: Nb ventes COSAP ≥ 2 Taux remplissage équipes ≥ 90% (mensuel) | L20: =IF(F20="Terminé","À évaluer (J+90)","En attente") -> En attente
A21: OQ-14 | B21: PR2 — BU Digital & Entreprises | C21: Haute | D21: Packager l'offre SFM Connect. Prospecter France (3 clients), Tunisie (5 clients) et 3 pays africains (1 client/pays). Suivre le CA mensuel. | E21: Dir. Exécutif Digital / Resp. Commercial | F21: Planifié | G21: 46387 | H21: =IF(AND(G21<TODAY(),F21<>"Terminé"),"⚠️ RETARD","") | I21: Q1 : Offre SFM Connect packagée Q2 : 3 clients France signés Q4 : 50 k€ CA atteint | J21: Resp. Commercial · Équipe technique PR2 · Budget prospection internationale · CRM | K21: CA SFM Connect ≥ 50 k€ Nb clients = 9 (trimestriel) | L21: =IF(F21="Terminé","À évaluer (J+90)","En attente") -> En attente
A22: OQ-15 | B22: PR2 — BU Digital & Entreprises | C22: Haute | D22: Finaliser le développement SoC et SIEM. Réaliser 2 PoCs ou démonstrations. Signer 2 contrats pilotes avant fin septembre 2026. | E22: Dir. Exécutif Digital / Chef BU | F22: En cours | G22: 46295 | H22: =IF(AND(G22<TODAY(),F22<>"Terminé"),"⚠️ RETARD","") | I22: Q1 : Produits SoC/SIEM finalisés Q2 : 1er PoC réalisé Q3 : 2 PoCs/ventes signés | J22: Équipe technique · Budget cybersécurité · Experts SoC/SIEM · Resp. Commercial | K22: Nb PoCs/ventes SoC/SIEM ≥ 2 (mensuel) | L22: =IF(F22="Terminé","À évaluer (J+90)","En attente") -> En attente
A23: OQ-16 | B23: PR2 — BU Digital & Entreprises | C23: Haute | D23: Développer BidMaster V1. Déployer en S1 2026. Mesurer le gain d'efficacité dans les réponses AO/AMI. Objectif : 80% de temps économisé. | E23: Dir. Exécutif Digital / PMO | F23: En cours | G23: 46203 | H23: =IF(AND(G23<TODAY(),F23<>"Terminé"),"⚠️ RETARD","") | I23: Mar : BidMaster V1 développé Avr : Tests et validation Juin : Déploiement + mesure gains | J23: Budget IA · Équipe dev. BidMaster · PMO-Qualité · Dir. Commercial | K23: BidMaster V1 déployé (Oui) Gain efficacité AO ≥ 80% (mensuel) | L23: =IF(F23="Terminé","À évaluer (J+90)","En attente") -> En attente
A24: OQ-17 | B24: PR2 — BU Digital & Entreprises | C24: Haute | D24: Développer KMS SFM BrAIn V1. Intégrer la base de connaissances interne. Sécuriser les codes SFM. Déployer en S1 2026. | E24: Dir. Exécutif Digital / Resp. IT | F24: En cours | G24: 46203 | H24: =IF(AND(G24<TODAY(),F24<>"Terminé"),"⚠️ RETARD","") | I24: Mar : Architecture KMS définie Avr : Base connaissance intégrée Juin : KMS V1 opérationnel | J24: Resp. IT · Équipe dev. KMS · Budget IA/R&D · GED COSAP | K24: KMS V1 opérationnel (Oui) Nb processus documentés = 100% (mensuel) | L24: =IF(F24="Terminé","À évaluer (J+90)","En attente") -> En attente
A25: OQ-18 | B25: PR2 — BU Digital & Entreprises | C25: Haute | D25: Démarrer le projet site web. Valider la charte graphique. Développer et déployer avant le 31/05/2026. Assurer compatibilité SEO et ISO. | E25: Resp. Commercial / Dir. Exécutif Digital | F25: En cours | G25: 46173 | H25: =IF(AND(G25<TODAY(),F25<>"Terminé"),"⚠️ RETARD","") -> ⚠️ RETARD | I25: Fév : Maquettes validées Avr : Développement terminé 31/05 : Site en ligne | J25: Resp. Commercial · Équipe web · Budget refonte site (estimé : 3-5 k€) | K25: Site opérationnel avant 31/05/2026 (Oui/Non) | L25: =IF(F25="Terminé","À évaluer (J+90)","En attente") -> En attente
A26: OQ-19 | B26: PR2 — BU Digital & Entreprises | C26: Haute | D26: Optimiser les charges BU Digital. Augmenter le CA par diversification produits. Produire un reporting mensuel financier BU Digital. | E26: Dir. Exécutif Digital / RAF | F26: En cours | G26: 46387 | H26: =IF(AND(G26<TODAY(),F26<>"Terminé"),"⚠️ RETARD","") | I26: Q1 : Objectifs CA BU Digital fixés Q2 : Bilan S1 Q4 : Marge nette ≥ 30% atteinte | J26: Dir. Exécutif Digital · RAF · COSAP · Tableaux de bord financiers | K26: Marge nette BU Digital ≥ 30% (trimestriel) | L26: =IF(F26="Terminé","À évaluer (J+90)","En attente") -> En attente
A27: PR3 — RÉALISATION : BU Formation
A28: OQ-20 | B28: PR3 — Formation | C28: Moyenne | D28: Définir l'objectif CA Formation avec la direction. Intégrer l'IA dans les programmes et l'ingénierie pédagogique. Suivre le CA mensuel. | E28: Resp. Formation / Direction | F28: À planifier | G28: 46112 | H28: =IF(AND(G28<TODAY(),F28<>"Terminé"),"⚠️ RETARD","") -> ⚠️ RETARD | I28: Jan : Cible CA Formation validée Q2 : IA intégrée aux programmes Q4 : Bilan CA Formation | J28: Resp. Formation · Direction · Budget pédagogique · Outils IA formation | K28: CA Formation atteint (cible MS) IA intégrée (Oui/Non) (trimestriel) | L28: =IF(F28="Terminé","À évaluer (J+90)","En attente") -> En attente
A29: OQ-21 | B29: PR3 — Formation | C29: Haute | D29: Définir le cahier des charges des 5 modules. Produire les contenus (5G, IA, Cybersécurité, Data). Valider et commercialiser. | E29: Resp. Formation / Chef BU PR3 | F29: Planifié | G29: 46295 | H29: =IF(AND(G29<TODAY(),F29<>"Terminé"),"⚠️ RETARD","") | I29: Q1 : Cahiers des charges Q2 : 2 modules produits Q3 : 5 modules livrés et validés | J29: Resp. Formation · Experts techniques BU · Plateforme e-learning · Budget production | K29: Nb modules formation ≥ 5 (semestriel) | L29: =IF(F29="Terminé","À évaluer (J+90)","En attente") -> En attente
A30: OQ-22 | B30: PR3 — Formation | C30: Haute | D30: Déployer questionnaires satisfaction en fin de session. Suivre taux de réussite. Obtenir attestations pour 100% des programmes en cours. | E30: Resp. Formation / Resp. Qualité | F30: À planifier | G30: 46295 | H30: =IF(AND(G30<TODAY(),F30<>"Terminé"),"⚠️ RETARD","") | I30: Q1 : Questionnaire déployé Q2 : 1ère analyse bilan S1 Q3 : 90% satisfaction atteint | J30: Resp. Formation · Outil enquête · PMO-Qualité · Resp. Qualité | K30: Taux satisfaction ≥ 90% Taux réussite ≥ 80% (trimestriel) | L30: =IF(F30="Terminé","À évaluer (J+90)","En attente") -> En attente
A31: PS1 — SUPPORT : RH & Compétences
A32: OQ-23 | B32: PS1 — RH & Compétences | C32: Moyenne | D32: Concevoir et déployer un questionnaire de satisfaction collaborateurs semestriel. Analyser les résultats. Définir un plan d'action correctif. | E32: DRH / Resp. RH | F32: À planifier | G32: 46203 | H32: =IF(AND(G32<TODAY(),F32<>"Terminé"),"⚠️ RETARD","") | I32: Q1 : Questionnaire conçu Q2 : 1ère enquête réalisée Q3-Q4 : 2ème enquête + analyse | J32: DRH · Outil enquête (Google Forms/COSAP) · Direction | K32: Taux satisfaction ≥ 80% (semestriel) | L32: =IF(F32="Terminé","À évaluer (J+90)","En attente") -> En attente
A33: OQ-24 | B33: PS1 — RH & Compétences | C33: Moyenne | D33: Établir matrice de polyvalence des équipes techniques. Planifier des rotations de mission. Valoriser les collaborateurs polyvalents. | E33: DRH / Chef BU | F33: À planifier | G33: 46387 | H33: =IF(AND(G33<TODAY(),F33<>"Terminé"),"⚠️ RETARD","") | I33: Q1 : Matrice polyvalence créée Q2 : Premières affectations croisées Q4 : Bilan annuel | J33: DRH · Chefs de BU · Matrice compétences (COSAP) | K33: % collaborateurs polyvalents = 100% (annuel) | L33: =IF(F33="Terminé","À évaluer (J+90)","En attente") -> En attente
A34: OQ-25 | B34: PS1 — RH & Compétences | C34: Haute | D34: Identifier les postes critiques. Former un doublon pour chaque poste critique (priorité : TariStriker). Documenter les compétences clés. | E34: DRH / Resp. RH | F34: Planifié | G34: 46295 | H34: =IF(AND(G34<TODAY(),F34<>"Terminé"),"⚠️ RETARD","") | I34: Q1 : Postes critiques identifiés Q2 : Plan formation doublons Q3 : Doublons formés | J34: DRH · Chefs BU · Budget formation · Plan de succession | K34: Nb postes critiques avec doublon = 100% (semestriel) | L34: =IF(F34="Terminé","À évaluer (J+90)","En attente") -> En attente
A35: PS2 — SUPPORT : Finance & Administration
A36: OQ-26 | B36: PS2 — Finance & Admin | C36: Haute | D36: Mettre en place suivi de recouvrement (relances J+30 et J+45). Intégrer clauses de pénalité dans les contrats. Tableau de bord recouvrement. | E36: Resp. Finance / RAF | F36: En cours | G36: 46203 | H36: =IF(AND(G36<TODAY(),F36<>"Terminé"),"⚠️ RETARD","") | I36: Jan : Procédure recouvrement rédigée Fév : Clauses contrats révisées Q2 : TDB opérationnel | J36: RAF · Modèles contrats révisés · Module financier COSAP · Conseil juridique | K36: Taux recouvrement ≥ 90% (mensuel) Nb factures en retard > J+60 | L36: =IF(F36="Terminé","À évaluer (J+90)","En attente") -> En attente
A37: OQ-27 | B37: PS2 — Finance & Admin | C37: Haute | D37: Automatiser la production des KPIs financiers via COSAP. Diffuser par mail à la responsable financière et DG. Zéro erreur de calcul. | E37: Resp. Finance / RAF | F37: En cours | G37: 46112 | H37: =IF(AND(G37<TODAY(),F37<>"Terminé"),"⚠️ RETARD","") -> ⚠️ RETARD | I37: Jan : Module COSAP Finance finalisé Fév : Tests et validation Mar : Diffusion automatisée | J37: Module financier COSAP · RAF · Resp. Finance · Direction | K37: Nb rapports sans erreur / total = 100% (mensuel) | L37: =IF(F37="Terminé","À évaluer (J+90)","En attente") -> En attente
A38: OQ-28 | B38: PS2 — Finance & Admin | C38: Haute | D38: Finaliser le développement du module financier COSAP. Tester les fonctionnalités. Déployer en production avant fin Q1 2026. | E38: RAF / PMO-Qualité | F38: En cours | G38: 46112 | H38: =IF(AND(G38<TODAY(),F38<>"Terminé"),"⚠️ RETARD","") -> ⚠️ RETARD | I38: Jan : Fonctionnalités finalisées Fév : Tests recette Mar : Mise en production | J38: PMO-Qualité · RAF · Équipe dev. COSAP · Budget | K38: Module COSAP Finance opérationnel (Oui/Non) | L38: =IF(F38="Terminé","À évaluer (J+90)","En attente") -> En attente
A39: OQ-29 | B39: PS2 — Finance & Admin | C39: Haute | D39: Mettre en place des revues de qualité des états financiers. Former l'équipe aux bonnes pratiques comptables. Audit interne semestriel. | E39: RAF / Resp. Finance | F39: En cours | G39: 46387 | H39: =IF(AND(G39<TODAY(),F39<>"Terminé"),"⚠️ RETARD","") | I39: Q1 : Procédure vérification établie Q2 : 1er audit interne finance Q4 : Bilan annuel | J39: RAF · Resp. Finance · Comptable · Outils COSAP | K39: % états financiers sans erreur ≥ 95% (trimestriel) | L39: =IF(F39="Terminé","À évaluer (J+90)","En attente") -> En attente
A40: OQ-30 | B40: PS2 — Finance & Admin | C40: Moyenne | D40: Mettre en place calendrier fiscal et social. Assurer la veille réglementaire. Déposer toutes les déclarations en avance. Zéro pénalité. | E40: RAF / Resp. Finance | F40: Maintenu | G40: 46387 | H40: =IF(AND(G40<TODAY(),F40<>"Terminé"),"⚠️ RETARD","") | I40: Q1 : Calendrier fiscal établi Q2 : 1ère revue conformité Q4 : Bilan zéro pénalité | J40: RAF · Resp. Finance · Conseil fiscal/juridique · Calendrier fiscal | K40: Nb retards/pénalités = 0 (trimestriel) | L40: =IF(F40="Terminé","À évaluer (J+90)","En attente") -> En attente
A41: PS3 — SUPPORT : Infrastructure IT & Systèmes d'Information
...

Sheet 03_SUIVI_DATA
A1: 📊 SUIVI MENSUEL DES DONNÉES KPI | SFM TECHNOLOGIES | ISO 9001:2015 | 2026
A2: 🗓️ Mois actif : | E2: Juin | G2: 💡 Formule liaison → col K Feuille 1 : =IFERROR(INDEX('03_SUIVI_DATA'!$E$5:$P$100,MATCH($A2,'03_SUIVI_DATA'!$B$5:$B$100,0),MATCH('03_SUIVI_DATA'!$E$2,'03_SUIVI_DATA'!$E$4:$P$4,0)),"") | S2: ⚡ SPARKLINES : Sélectionner R6:R53 > Insertion > Sparklines > Courbes > Plage E6:P53
A4: Processus | B4: Réf. | C4: Indicateur KPI | D4: Unité | E4: Janv. | F4: Févr. | G4: Mars | H4: Avr. | I4: Mai | J4: Juin | K4: Juill. | L4: Août | M4: Sept. | N4: Oct. | O4: Nov. | P4: Déc. | Q4: Cible 2026 | R4: 📈 Tendance (Sparkline*)
A5: PM1 — MANAGEMENT : Planification Stratégique & Objectifs Qualité
A6: PM1 | B6: OQ-01 | C6: CA 2026 / CA 2024 × 100 | D6: % | Q6: 0.3 | R6: =IFERROR(LOOKUP(2,1/(E6:P6<>""),E6:P6),"")
A7: PM1 | B7: OQ-02 | C7: Nb modifications roadmap / an | D7: Nb | Q7: 1 | R7: =IFERROR(LOOKUP(2,1/(E7:P7<>""),E7:P7),"")
A8: PM1 | B8: OQ-03 | C8: % gain productivité IA mesuré vs baseline 2025 | D8: Nb | Q8: 0.2 | R8: =IFERROR(LOOKUP(2,1/(E8:P8<>""),E8:P8),"")
A9: PM1 | B9: OQ-04 | C9: Nb pays avec partenaire local actif / 6 | D9: Nb | Q9: 6 | R9: =IFERROR(LOOKUP(2,1/(E9:P9<>""),E9:P9),"")
A10: PM1 | B10: OQ-05 | C10: % temps équipes tech. contractualisé / temps dispo | D10: Nb | Q10: 0.5 | R10: =IFERROR(LOOKUP(2,1/(E10:P10<>""),E10:P10),"")
A11: PR1 — RÉALISATION : BU Conseil, Ingénierie & Solutions Telco
A12: PR1 | B12: OQ-06 | C12: Nb contrats cybersécurité signés / an | D12: Nb | Q12: 2 | R12: =IFERROR(LOOKUP(2,1/(E12:P12<>""),E12:P12),"")
A13: PR1 | B13: OQ-07 | C13: Migration réalisée (Oui/Non) | D13: O/N | Q13: 5 | R13: =IFERROR(LOOKUP(2,1/(E13:P13<>""),E13:P13),"")
A14: PR1 | B14: OQ-08 | C14: Prototype fonctionnel livré (Oui/Non) | D14: O/N | Q14: 1 | R14: =IFERROR(LOOKUP(2,1/(E14:P14<>""),E14:P14),"")
A15: PR1 | B15: OQ-09 | C15: Nb études publiées + Nb projets TIC signés | D15: Nb | Q15: 15 | R15: =IFERROR(LOOKUP(2,1/(E15:P15<>""),E15:P15),"")
A16: PR1 | B16: OQ-10 | C16: % projets Telco avec attestation bonne fin dans dé | D16: Jours | Q16: 0.8 | R16: =IFERROR(LOOKUP(2,1/(E16:P16<>""),E16:P16),"")
A17: PR1 | B17: OQ-11 | C17: Nb nouveaux clients anglophones signés (hors prosp | D17: Nb | Q17: 3 | R17: =IFERROR(LOOKUP(2,1/(E17:P17<>""),E17:P17),"")
A18: PR1 | B18: OQ-12 | C18: CA BU Telco 2026 / CA 2024 × 100 | D18: % | Q18: 0.2 | R18: =IFERROR(LOOKUP(2,1/(E18:P18<>""),E18:P18),"")
A19: PR2 — RÉALISATION : BU Conseil, Transformation Digitale & Solutions Entreprises
A20: PR2 | B20: OQ-13 | C20: Nb ventes COSAP + Taux remplissage équipes (%) | D20: % | Q20: 2 | R20: =IFERROR(LOOKUP(2,1/(E20:P20<>""),E20:P20),"")
A21: PR2 | B21: OQ-14 | C21: CA SFM Connect 2026 (k€) | D21: k€ | Q21: 50 | R21: =IFERROR(LOOKUP(2,1/(E21:P21<>""),E21:P21),"")
A22: PR2 | B22: OQ-15 | C22: Nb PoCs ou ventes SoC/SIEM signés avant Q3 2026 | D22: Nb | Q22: 2 | R22: =IFERROR(LOOKUP(2,1/(E22:P22<>""),E22:P22),"")
A23: PR2 | B23: OQ-16 | C23: BidMaster V1 déployé (Oui/Non) | D23: O/N | Q23: 0.8 | R23: =IFERROR(LOOKUP(2,1/(E23:P23<>""),E23:P23),"")
A24: PR2 | B24: OQ-17 | C24: KMS V1 opérationnel (Oui/Non) | D24: O/N | Q24: 1 | R24: =IFERROR(LOOKUP(2,1/(E24:P24<>""),E24:P24),"")
A25: PR2 | B25: OQ-18 | C25: Site web lancé avant 31/05/2026 (Oui/Non) | D25: O/N | Q25: 1 | R25: =IFERROR(LOOKUP(2,1/(E25:P25<>""),E25:P25),"")
A26: PR2 | B26: OQ-19 | C26: Marge nette BU Digital / CA BU Digital × 100 | D26: % | Q26: 0.3 | R26: =IFERROR(LOOKUP(2,1/(E26:P26<>""),E26:P26),"")
A27: PR3 — RÉALISATION : BU Formation
A28: PR3 | B28: OQ-20 | C28: CA BU Formation 2026 (k€) | D28: O/N | Q28: 1 | R28: =IFERROR(LOOKUP(2,1/(E28:P28<>""),E28:P28),"")
A29: PR3 | B29: OQ-21 | C29: Nb nouveaux modules formation livrés et validés en | D29: Nb | Q29: 5 | R29: =IFERROR(LOOKUP(2,1/(E29:P29<>""),E29:P29),"")
A30: PR3 | B30: OQ-22 | C30: Taux satisfaction apprenants (%) | D30: % | Q30: 0.9 | R30: =IFERROR(LOOKUP(2,1/(E30:P30<>""),E30:P30),"")
A31: PS1 — SUPPORT : RH & Compétences
A32: PS1 | B32: OQ-23 | C32: Taux satisfaction collaborateurs (enquête semestri | D32: % | Q32: 0.8 | R32: =IFERROR(LOOKUP(2,1/(E32:P32<>""),E32:P32),"")
A33: PS1 | B33: OQ-24 | C33: % collaborateurs techniques ayant participé à 1 pr | D33: Nb | Q33: 1 | R33: =IFERROR(LOOKUP(2,1/(E33:P33<>""),E33:P33),"")
A34: PS1 | B34: OQ-25 | C34: Nb postes critiques avec doublon formé / nb postes | D34: Nb | Q34: 1 | R34: =IFERROR(LOOKUP(2,1/(E34:P34<>""),E34:P34),"")
A35: PS2 — SUPPORT : Finance & Administration
A36: PS2 | B36: OQ-26 | C36: Montant recouvré dans J+60 / montant facturé × 100 | D36: % | Q36: 0.9 | R36: =IFERROR(LOOKUP(2,1/(E36:P36<>""),E36:P36),"")
A37: PS2 | B37: OQ-27 | C37: Nb rapports financiers envoyés / nb mois × 100 | D37: % | Q37: 1 | R37: =IFERROR(LOOKUP(2,1/(E37:P37<>""),E37:P37),"")
A38: PS2 | B38: OQ-28 | C38: Module COSAP Finance opérationnel (Oui/Non) | D38: O/N | Q38: 1 | R38: =IFERROR(LOOKUP(2,1/(E38:P38<>""),E38:P38),"")
A39: PS2 | B39: OQ-29 | C39: % états financiers sans erreur significative / an | D39: Nb | Q39: 0.95 | R39: =IFERROR(LOOKUP(2,1/(E39:P39<>""),E39:P39),"")
A40: PS2 | B40: OQ-30 | C40: Nb retards ou pénalités déclarations fiscales/soci | D40: Nb | Q40: 0 | R40: =IFERROR(LOOKUP(2,1/(E40:P40<>""),E40:P40),"")
A41: PS3 — SUPPORT : Infrastructure IT & Systèmes d'Information
...

Sheet _MOTEUR_
A1: Proc | B1: Libellé | C1: Score
A2: PM1 | B2: Planif. Stratégique | C2: =IFERROR(AVERAGEIF('6.2.1 Objectifs SMART'!$B:$B,"PM1*",'6.2.1 Objectifs SMART'!$L:$L),0) -> 0.2
A3: PR1 | B3: BU Telco | C3: =IFERROR(AVERAGEIF('6.2.1 Objectifs SMART'!$B:$B,"PR1*",'6.2.1 Objectifs SMART'!$L:$L),0) -> 0
A4: PR2 | B4: BU Digital | C4: =IFERROR(AVERAGEIF('6.2.1 Objectifs SMART'!$B:$B,"PR2*",'6.2.1 Objectifs SMART'!$L:$L),0) -> 0
A5: PR3 | B5: BU Formation | C5: =IFERROR(AVERAGEIF('6.2.1 Objectifs SMART'!$B:$B,"PR3*",'6.2.1 Objectifs SMART'!$L:$L),0) -> 0
A6: PS1 | B6: RH & Compétences | C6: =IFERROR(AVERAGEIF('6.2.1 Objectifs SMART'!$B:$B,"PS1*",'6.2.1 Objectifs SMART'!$L:$L),0) -> 0
A7: PS2 | B7: Finance & Admin | C7: =IFERROR(AVERAGEIF('6.2.1 Objectifs SMART'!$B:$B,"PS2*",'6.2.1 Objectifs SMART'!$L:$L),0) -> 0
A8: PS3 | B8: Infrastructure IT | C8: =IFERROR(AVERAGEIF('6.2.1 Objectifs SMART'!$B:$B,"PS3*",'6.2.1 Objectifs SMART'!$L:$L),0) -> 0
A9: PS4 | B9: Commercial B.O. | C9: =IFERROR(AVERAGEIF('6.2.1 Objectifs SMART'!$B:$B,"PS4*",'6.2.1 Objectifs SMART'!$L:$L),0) -> 0
A10: PS5 | B10: Mgmt Qualité | C10: =IFERROR(AVERAGEIF('6.2.1 Objectifs SMART'!$B:$B,"PS5*",'6.2.1 Objectifs SMART'!$L:$L),0) -> 0
